[2025-05-29T03:16:54.185+0000] {taskinstance.py:1956} INFO - Dependencies all met for dep_context=non-requeueable deps ti=<TaskInstance: etl_ecobici.procesar_datos manual__2025-05-29T03:16:30.118274+00:00 [queued]>
[2025-05-29T03:16:54.206+0000] {taskinstance.py:1956} INFO - Dependencies all met for dep_context=requeueable deps ti=<TaskInstance: etl_ecobici.procesar_datos manual__2025-05-29T03:16:30.118274+00:00 [queued]>
[2025-05-29T03:16:54.207+0000] {taskinstance.py:2170} INFO - Starting attempt 1 of 1
[2025-05-29T03:16:54.260+0000] {taskinstance.py:2191} INFO - Executing <Task(PythonOperator): procesar_datos> on 2025-05-29 03:16:30.118274+00:00
[2025-05-29T03:16:54.264+0000] {standard_task_runner.py:60} INFO - Started process 51 to run task
[2025-05-29T03:16:54.269+0000] {standard_task_runner.py:87} INFO - Running: ['airflow', 'tasks', 'run', 'etl_ecobici', 'procesar_datos', 'manual__2025-05-29T03:16:30.118274+00:00', '--job-id', '3', '--raw', '--subdir', 'DAGS_FOLDER/etl_ecobici.py', '--cfg-path', '/tmp/tmpwuyei2pg']
[2025-05-29T03:16:54.272+0000] {standard_task_runner.py:88} INFO - Job 3: Subtask procesar_datos
[2025-05-29T03:16:54.434+0000] {task_command.py:423} INFO - Running <TaskInstance: etl_ecobici.procesar_datos manual__2025-05-29T03:16:30.118274+00:00 [running]> on host ec4e5ac5fc82
[2025-05-29T03:16:54.689+0000] {taskinstance.py:2480} INFO - Exporting env vars: AIRFLOW_CTX_DAG_OWNER='airflow' AIRFLOW_CTX_DAG_ID='etl_ecobici' AIRFLOW_CTX_TASK_ID='procesar_datos' AIRFLOW_CTX_EXECUTION_DATE='2025-05-29T03:16:30.118274+00:00' AIRFLOW_CTX_TRY_NUMBER='1' AIRFLOW_CTX_DAG_RUN_ID='manual__2025-05-29T03:16:30.118274+00:00'
[2025-05-29T03:16:54.702+0000] {taskinstance.py:2698} ERROR - Task failed with exception
Traceback (most recent call last):
  File "/home/airflow/.local/lib/python3.10/site-packages/airflow/models/taskinstance.py", line 433, in _execute_task
    result = execute_callable(context=context, **execute_callable_kwargs)
  File "/home/airflow/.local/lib/python3.10/site-packages/airflow/operators/python.py", line 199, in execute
    return_value = self.execute_callable()
  File "/home/airflow/.local/lib/python3.10/site-packages/airflow/operators/python.py", line 216, in execute_callable
    return self.python_callable(*self.op_args, **self.op_kwargs)
  File "/opt/airflow/dags/etl_ecobici.py", line 23, in procesar_datos
    subprocess.run(["spark-submit", "dags/scripts/procesar_ecobici.py"], check=True)
  File "/usr/local/lib/python3.10/subprocess.py", line 503, in run
    with Popen(*popenargs, **kwargs) as process:
  File "/usr/local/lib/python3.10/subprocess.py", line 971, in __init__
    self._execute_child(args, executable, preexec_fn, close_fds,
  File "/usr/local/lib/python3.10/subprocess.py", line 1863, in _execute_child
    raise child_exception_type(errno_num, err_msg, err_filename)
PermissionError: [Errno 13] Permission denied: 'spark-submit'
[2025-05-29T03:16:54.732+0000] {taskinstance.py:1138} INFO - Marking task as FAILED. dag_id=etl_ecobici, task_id=procesar_datos, execution_date=20250529T031630, start_date=20250529T031654, end_date=20250529T031654
[2025-05-29T03:16:54.780+0000] {standard_task_runner.py:107} ERROR - Failed to execute job 3 for task procesar_datos ([Errno 13] Permission denied: 'spark-submit'; 51)
[2025-05-29T03:16:54.804+0000] {local_task_job_runner.py:234} INFO - Task exited with return code 1
[2025-05-29T03:16:54.845+0000] {taskinstance.py:3280} INFO - 0 downstream tasks scheduled from follow-on schedule check
