[2025-05-29T18:27:29.201+0000] {taskinstance.py:1956} INFO - Dependencies all met for dep_context=non-requeueable deps ti=<TaskInstance: etl_ecobici.procesar_datos manual__2025-05-29T03:16:30.118274+00:00 [queued]>
[2025-05-29T18:27:29.234+0000] {taskinstance.py:1956} INFO - Dependencies all met for dep_context=requeueable deps ti=<TaskInstance: etl_ecobici.procesar_datos manual__2025-05-29T03:16:30.118274+00:00 [queued]>
[2025-05-29T18:27:29.235+0000] {taskinstance.py:2170} INFO - Starting attempt 3 of 3
[2025-05-29T18:27:29.293+0000] {taskinstance.py:2191} INFO - Executing <Task(PythonOperator): procesar_datos> on 2025-05-29 03:16:30.118274+00:00
[2025-05-29T18:27:29.298+0000] {standard_task_runner.py:60} INFO - Started process 125 to run task
[2025-05-29T18:27:29.302+0000] {standard_task_runner.py:87} INFO - Running: ['airflow', 'tasks', 'run', 'etl_ecobici', 'procesar_datos', 'manual__2025-05-29T03:16:30.118274+00:00', '--job-id', '5', '--raw', '--subdir', 'DAGS_FOLDER/etl_ecobici.py', '--cfg-path', '/tmp/tmprfvopetj']
[2025-05-29T18:27:29.305+0000] {standard_task_runner.py:88} INFO - Job 5: Subtask procesar_datos
[2025-05-29T18:27:29.503+0000] {task_command.py:423} INFO - Running <TaskInstance: etl_ecobici.procesar_datos manual__2025-05-29T03:16:30.118274+00:00 [running]> on host ec4e5ac5fc82
[2025-05-29T18:27:29.794+0000] {taskinstance.py:2480} INFO - Exporting env vars: AIRFLOW_CTX_DAG_OWNER='airflow' AIRFLOW_CTX_DAG_ID='etl_ecobici' AIRFLOW_CTX_TASK_ID='procesar_datos' AIRFLOW_CTX_EXECUTION_DATE='2025-05-29T03:16:30.118274+00:00' AIRFLOW_CTX_TRY_NUMBER='3' AIRFLOW_CTX_DAG_RUN_ID='manual__2025-05-29T03:16:30.118274+00:00'
[2025-05-29T18:27:29.854+0000] {taskinstance.py:2698} ERROR - Task failed with exception
Traceback (most recent call last):
  File "/home/airflow/.local/lib/python3.10/site-packages/airflow/models/taskinstance.py", line 433, in _execute_task
    result = execute_callable(context=context, **execute_callable_kwargs)
  File "/home/airflow/.local/lib/python3.10/site-packages/airflow/operators/python.py", line 199, in execute
    return_value = self.execute_callable()
  File "/home/airflow/.local/lib/python3.10/site-packages/airflow/operators/python.py", line 216, in execute_callable
    return self.python_callable(*self.op_args, **self.op_kwargs)
  File "/opt/airflow/dags/etl_ecobici.py", line 23, in procesar_datos
    subprocess.run([
  File "/usr/local/lib/python3.10/subprocess.py", line 526, in run
    raise CalledProcessError(retcode, process.args,
subprocess.CalledProcessError: Command '['docker', 'exec', 'spark', 'spark-submit', '/app/dags/scripts/procesar_ecobici.py']' returned non-zero exit status 1.
[2025-05-29T18:27:29.896+0000] {taskinstance.py:1138} INFO - Marking task as FAILED. dag_id=etl_ecobici, task_id=procesar_datos, execution_date=20250529T031630, start_date=20250529T182729, end_date=20250529T182729
[2025-05-29T18:27:29.979+0000] {standard_task_runner.py:107} ERROR - Failed to execute job 5 for task procesar_datos (Command '['docker', 'exec', 'spark', 'spark-submit', '/app/dags/scripts/procesar_ecobici.py']' returned non-zero exit status 1.; 125)
[2025-05-29T18:27:30.001+0000] {local_task_job_runner.py:234} INFO - Task exited with return code 1
[2025-05-29T18:27:30.052+0000] {taskinstance.py:3280} INFO - 0 downstream tasks scheduled from follow-on schedule check
