[2025-05-30T11:52:32.462+0000] {taskinstance.py:1956} INFO - Dependencies all met for dep_context=non-requeueable deps ti=<TaskInstance: etl_ecobici.procesar_datos manual__2025-05-30T11:52:05.911228+00:00 [queued]>
[2025-05-30T11:52:32.500+0000] {taskinstance.py:1956} INFO - Dependencies all met for dep_context=requeueable deps ti=<TaskInstance: etl_ecobici.procesar_datos manual__2025-05-30T11:52:05.911228+00:00 [queued]>
[2025-05-30T11:52:32.501+0000] {taskinstance.py:2170} INFO - Starting attempt 1 of 1
[2025-05-30T11:52:32.589+0000] {taskinstance.py:2191} INFO - Executing <Task(PythonOperator): procesar_datos> on 2025-05-30 11:52:05.911228+00:00
[2025-05-30T11:52:32.596+0000] {standard_task_runner.py:60} INFO - Started process 54 to run task
[2025-05-30T11:52:32.601+0000] {standard_task_runner.py:87} INFO - Running: ['airflow', 'tasks', 'run', 'etl_ecobici', 'procesar_datos', 'manual__2025-05-30T11:52:05.911228+00:00', '--job-id', '13', '--raw', '--subdir', 'DAGS_FOLDER/etl_ecobici.py', '--cfg-path', '/tmp/tmp8m72de39']
[2025-05-30T11:52:32.604+0000] {standard_task_runner.py:88} INFO - Job 13: Subtask procesar_datos
[2025-05-30T11:52:32.785+0000] {task_command.py:423} INFO - Running <TaskInstance: etl_ecobici.procesar_datos manual__2025-05-30T11:52:05.911228+00:00 [running]> on host 3fdc887dd89b
[2025-05-30T11:52:32.997+0000] {taskinstance.py:2480} INFO - Exporting env vars: AIRFLOW_CTX_DAG_OWNER='airflow' AIRFLOW_CTX_DAG_ID='etl_ecobici' AIRFLOW_CTX_TASK_ID='procesar_datos' AIRFLOW_CTX_EXECUTION_DATE='2025-05-30T11:52:05.911228+00:00' AIRFLOW_CTX_TRY_NUMBER='1' AIRFLOW_CTX_DAG_RUN_ID='manual__2025-05-30T11:52:05.911228+00:00'
[2025-05-30T11:52:33.081+0000] {taskinstance.py:2698} ERROR - Task failed with exception
Traceback (most recent call last):
  File "/home/airflow/.local/lib/python3.10/site-packages/airflow/models/taskinstance.py", line 433, in _execute_task
    result = execute_callable(context=context, **execute_callable_kwargs)
  File "/home/airflow/.local/lib/python3.10/site-packages/airflow/operators/python.py", line 199, in execute
    return_value = self.execute_callable()
  File "/home/airflow/.local/lib/python3.10/site-packages/airflow/operators/python.py", line 216, in execute_callable
    return self.python_callable(*self.op_args, **self.op_kwargs)
  File "/opt/airflow/dags/etl_ecobici.py", line 23, in procesar_datos
    subprocess.run([
  File "/usr/local/lib/python3.10/subprocess.py", line 526, in run
    raise CalledProcessError(retcode, process.args,
subprocess.CalledProcessError: Command '['docker', 'exec', 'spark', 'spark-submit', '/app/dags/scripts/procesar_ecobici.py']' returned non-zero exit status 1.
[2025-05-30T11:52:33.101+0000] {taskinstance.py:1138} INFO - Marking task as FAILED. dag_id=etl_ecobici, task_id=procesar_datos, execution_date=20250530T115205, start_date=20250530T115232, end_date=20250530T115233
[2025-05-30T11:52:33.137+0000] {standard_task_runner.py:107} ERROR - Failed to execute job 13 for task procesar_datos (Command '['docker', 'exec', 'spark', 'spark-submit', '/app/dags/scripts/procesar_ecobici.py']' returned non-zero exit status 1.; 54)
[2025-05-30T11:52:33.177+0000] {local_task_job_runner.py:234} INFO - Task exited with return code 1
[2025-05-30T11:52:33.226+0000] {taskinstance.py:3280} INFO - 0 downstream tasks scheduled from follow-on schedule check
