[2025-05-30T13:47:39.845+0000] {taskinstance.py:1956} INFO - Dependencies all met for dep_context=non-requeueable deps ti=<TaskInstance: etl_ecobici.procesar_datos manual__2025-05-30T13:47:25.452795+00:00 [queued]>
[2025-05-30T13:47:39.866+0000] {taskinstance.py:1956} INFO - Dependencies all met for dep_context=requeueable deps ti=<TaskInstance: etl_ecobici.procesar_datos manual__2025-05-30T13:47:25.452795+00:00 [queued]>
[2025-05-30T13:47:39.866+0000] {taskinstance.py:2170} INFO - Starting attempt 1 of 1
[2025-05-30T13:47:39.917+0000] {taskinstance.py:2191} INFO - Executing <Task(DockerOperator): procesar_datos> on 2025-05-30 13:47:25.452795+00:00
[2025-05-30T13:47:39.923+0000] {standard_task_runner.py:60} INFO - Started process 92 to run task
[2025-05-30T13:47:39.928+0000] {standard_task_runner.py:87} INFO - Running: ['airflow', 'tasks', 'run', 'etl_ecobici', 'procesar_datos', 'manual__2025-05-30T13:47:25.452795+00:00', '--job-id', '33', '--raw', '--subdir', 'DAGS_FOLDER/etl_ecobici.py', '--cfg-path', '/tmp/tmp2bve6vmj']
[2025-05-30T13:47:39.930+0000] {standard_task_runner.py:88} INFO - Job 33: Subtask procesar_datos
[2025-05-30T13:47:40.038+0000] {task_command.py:423} INFO - Running <TaskInstance: etl_ecobici.procesar_datos manual__2025-05-30T13:47:25.452795+00:00 [running]> on host ff526de6184a
[2025-05-30T13:47:40.343+0000] {taskinstance.py:2480} INFO - Exporting env vars: AIRFLOW_CTX_DAG_OWNER='airflow' AIRFLOW_CTX_DAG_ID='etl_ecobici' AIRFLOW_CTX_TASK_ID='procesar_datos' AIRFLOW_CTX_EXECUTION_DATE='2025-05-30T13:47:25.452795+00:00' AIRFLOW_CTX_TRY_NUMBER='1' AIRFLOW_CTX_DAG_RUN_ID='manual__2025-05-30T13:47:25.452795+00:00'
[2025-05-30T13:47:40.368+0000] {docker.py:486} INFO - Pulling docker image bitnami/spark
[2025-05-30T13:47:42.719+0000] {docker.py:500} INFO - latest: Pulling from bitnami/spark
[2025-05-30T13:47:43.285+0000] {docker.py:500} INFO - f6ef761014f5: Pulling fs layer
[2025-05-30T13:47:44.645+0000] {docker.py:500} INFO - f6ef761014f5: Downloading
[2025-05-30T13:57:01.573+0000] {docker.py:500} INFO - f6ef761014f5: Retrying in 5 seconds
[2025-05-30T13:57:02.572+0000] {docker.py:500} INFO - f6ef761014f5: Retrying in 4 seconds
[2025-05-30T13:57:03.572+0000] {docker.py:500} INFO - f6ef761014f5: Retrying in 3 seconds
[2025-05-30T14:02:30.328+0000] {docker.py:500} INFO - f6ef761014f5: Retrying in 2 seconds
[2025-05-30T14:02:31.329+0000] {docker.py:500} INFO - f6ef761014f5: Retrying in 1 second
[2025-05-30T14:02:34.127+0000] {docker.py:500} INFO - f6ef761014f5: Downloading
[2025-05-30T14:06:14.933+0000] {docker.py:500} INFO - f6ef761014f5: Verifying Checksum
[2025-05-30T14:06:14.934+0000] {docker.py:500} INFO - f6ef761014f5: Download complete
[2025-05-30T14:06:14.978+0000] {docker.py:500} INFO - f6ef761014f5: Extracting
[2025-05-30T14:06:44.635+0000] {docker.py:500} INFO - f6ef761014f5: Pull complete
[2025-05-30T14:06:44.670+0000] {docker.py:495} INFO - Digest: sha256:2a7ac3c3e9f19cc9c73b3d0c2bce0d83a8a9aee06d607fdb381714f53c40b7a9
[2025-05-30T14:06:44.681+0000] {docker.py:495} INFO - Status: Downloaded newer image for bitnami/spark:latest
[2025-05-30T14:06:44.689+0000] {docker.py:359} INFO - Starting docker container from image bitnami/spark
[2025-05-30T14:06:44.719+0000] {taskinstance.py:2698} ERROR - Task failed with exception
Traceback (most recent call last):
  File "/home/airflow/.local/lib/python3.10/site-packages/docker/api/client.py", line 265, in _raise_for_status
    response.raise_for_status()
  File "/home/airflow/.local/lib/python3.10/site-packages/requests/models.py", line 1021, in raise_for_status
    raise HTTPError(http_error_msg, response=self)
requests.exceptions.HTTPError: 409 Client Error: Conflict for url: http+docker://localhost/v1.44/containers/create?name=spark

The above exception was the direct cause of the following exception:

Traceback (most recent call last):
  File "/home/airflow/.local/lib/python3.10/site-packages/airflow/models/taskinstance.py", line 433, in _execute_task
    result = execute_callable(context=context, **execute_callable_kwargs)
  File "/home/airflow/.local/lib/python3.10/site-packages/airflow/providers/docker/operators/docker.py", line 502, in execute
    return self._run_image()
  File "/home/airflow/.local/lib/python3.10/site-packages/airflow/providers/docker/operators/docker.py", line 376, in _run_image
    return self._run_image_with_mounts(self.mounts, add_tmp_variable=False)
  File "/home/airflow/.local/lib/python3.10/site-packages/airflow/providers/docker/operators/docker.py", line 391, in _run_image_with_mounts
    self.container = self.cli.create_container(
  File "/home/airflow/.local/lib/python3.10/site-packages/docker/api/container.py", line 439, in create_container
    return self.create_container_from_config(config, name, platform)
  File "/home/airflow/.local/lib/python3.10/site-packages/docker/api/container.py", line 456, in create_container_from_config
    return self._result(res, True)
  File "/home/airflow/.local/lib/python3.10/site-packages/docker/api/client.py", line 271, in _result
    self._raise_for_status(response)
  File "/home/airflow/.local/lib/python3.10/site-packages/docker/api/client.py", line 267, in _raise_for_status
    raise create_api_error_from_http_exception(e) from e
  File "/home/airflow/.local/lib/python3.10/site-packages/docker/errors.py", line 39, in create_api_error_from_http_exception
    raise cls(e, response=response, explanation=explanation) from e
docker.errors.APIError: 409 Client Error for http+docker://localhost/v1.44/containers/create?name=spark: Conflict ("Conflict. The container name "/spark" is already in use by container "3640672cf49b87e97b37e492456f4d861f72805583ee5616fb5de490bfa3e25e". You have to remove (or rename) that container to be able to reuse that name.")
[2025-05-30T14:06:44.761+0000] {taskinstance.py:1138} INFO - Marking task as FAILED. dag_id=etl_ecobici, task_id=procesar_datos, execution_date=20250530T134725, start_date=20250530T134739, end_date=20250530T140644
[2025-05-30T14:06:44.799+0000] {standard_task_runner.py:107} ERROR - Failed to execute job 33 for task procesar_datos (409 Client Error for http+docker://localhost/v1.44/containers/create?name=spark: Conflict ("Conflict. The container name "/spark" is already in use by container "3640672cf49b87e97b37e492456f4d861f72805583ee5616fb5de490bfa3e25e". You have to remove (or rename) that container to be able to reuse that name."); 92)
[2025-05-30T14:06:44.810+0000] {local_task_job_runner.py:234} INFO - Task exited with return code 1
[2025-05-30T14:06:45.055+0000] {taskinstance.py:3280} INFO - 0 downstream tasks scheduled from follow-on schedule check
